<?xml version="1.0" ?>
<!-- =================================================================================== -->
<!-- |    This document was autogenerated by xacro from simple.xacro                   | -->
<!-- |    EDITING THIS FILE BY HAND IS NOT RECOMMENDED                                 | -->
<!-- =================================================================================== -->
<robot name="simple_robot">
  <material name="black">
    <color rgba="0.0 0.0 0.0 1.0"/>
  </material>
  <material name="blue">
    <color rgba="0.0 0.0 0.8 1.0"/>
  </material>
  <material name="green">
    <color rgba="0.0 0.8 0.0 1.0"/>
  </material>
  <material name="grey">
    <color rgba="0.2 0.2 0.2 1.0"/>
  </material>
  <material name="orange">
    <color rgba="1.0 0.4235294117647059 0.0392156862745098 1.0"/>
  </material>
  <material name="brown">
    <color rgba="0.8705882352941177 0.8117647058823529 0.7647058823529411 1.0"/>
  </material>
  <material name="red">
    <color rgba="0.8 0.0 0.0 1.0"/>
  </material>
  <material name="white">
    <color rgba="1.0 1.0 1.0 1.0"/>
  </material>
  <link name="base_link">
    <visual>
      <geometry>
        <cylinder length="0.4" radius="0.4"/>
      </geometry>
      <!-- set visual origin in the coordinate frame of link -->
      <origin xyz="0 0 0.2"/>
      <material name="blue"/>
    </visual>
    <collision>
      <geometry>
        <cylinder length="0.4" radius="0.4"/>
      </geometry>
      <!-- set visual origin in the coordinate frame of link -->
      <origin xyz="0 0 0.2"/>
    </collision>
    <inertial>
      <mass value="1">1</mass>
      <inertia ixx="1.0" ixy="0.0" ixz="0.0" iyy="1.0" iyz="0.0" izz="1.0">
        <ixx>1</ixx>
        <ixy>0</ixy>
        <ixz>0</ixz>
        <iyy>1</iyy>
        <iyz>0</iyz>
        <izz>1</izz>
      </inertia>
    </inertial>
  </link>
  <link name="body_link">
    <visual>
      <geometry>
        <box size="0.3 0.3 0.6"/>
      </geometry>
      <material name="orange"/>
    </visual>
    <collision>
      <geometry>
        <box size="0.3 0.3 0.6"/>
      </geometry>
    </collision>
    <inertial>
      <mass value="1">1</mass>
      <inertia ixx="1.0" ixy="0.0" ixz="0.0" iyy="1.0" iyz="0.0" izz="1.0">
        <ixx>1</ixx>
        <ixy>0</ixy>
        <ixz>0</ixz>
        <iyy>1</iyy>
        <iyz>0</iyz>
        <izz>1</izz>
      </inertia>
    </inertial>
  </link>
  <joint name="base_body_joint" type="continuous">
    <parent link="base_link"/>
    <child link="body_link"/>
    <origin rpy="0 0 0" xyz="0 0 0.5"/>
    <axis xyz="0 0 1"/>
  </joint>
  <gazebo reference="base_link">
    <mu1>0.2</mu1>
    <mu2>0.2</mu2>
    <material>Gazebo/Blue</material>
  </gazebo>
  <gazebo reference="body_link">
    <mu1>0.2</mu1>
    <mu2>0.2</mu2>
    <material>Gazebo/Orange</material>
  </gazebo>
</robot>
