<?xml version="1.0"?>
<robot name="simple_robot" xmlns:xacro="http://ros.org/wiki/xacro">
  <xacro:include filename="./materials.xacro" />
  
  <link name="base_link">
    <visual>
      <geometry>
        <cylinder length="0.4" radius="0.4"/>
      </geometry>
      <!-- set visual origin in the coordinate frame of link -->
      <origin xyz="0 0 0.2"/>
      <material name="blue"/>
    </visual>
  </link>
  <link name="body_link">
    <visual>
      <geometry>
        <box size="0.3 0.3 0.6"/>
      </geometry>
      <material name="orange"/>
    </visual>
  </link>
  <joint name="base_body_joint" type="continuous">
    <parent link="base_link"/>
    <child link="body_link"/>
    <origin rpy="0 0 0" xyz="0 0 0.5"/>
    <axis xyz="0 0 1"/>
  </joint>
</robot>